Workbook
Name FromArray_1: _xlfn.ANCHORARRAY(#REF!)

Sheet regression
A1: 摘要輸出
A3: 迴歸統計
A4: R 的倍數 | B4: 0.98196563
A5: R 平方 | B5: 0.96425649
A6: 調整的 R 平方 | B6: 0.96391608
A7: 標準誤 | B7: 0.0092546139
A8: 觀察值個數 | B8: 107
A10: ANOVA
B11: 自由度 | C11: SS | D11: MS | E11: F | F11: 顯著值
A12: 迴歸 | B12: 1 | C12: 0.24260589 | D12: 0.24260589 | E12: 2832.5966 | F12: 8.7280057e-78
A13: 殘差 | B13: 105 | C13: 0.0089930272 | D13: 8.5647878e-05
A14: 總和 | B14: 106 | C14: 0.25159891
B16: 係數 | C16: 標準誤 | D16: t 統計 | E16: P-值 | F16: 下限 95% | G16: 上限 95% | H16: 下限 95.0% | I16: 上限 95.0%
A17: 截距 | B17: 0.00043210826 | C17: 0.00090723087 | D17: 0.4762936 | E17: 0.63485484 | F17: -0.001366763 | G17: 0.0022309795 | H17: -0.001366763 | I17: 0.0022309795
A18: 美洲基金 | B18: 0.93782536 | C18: 0.017620962 | D18: 53.222144 | E18: 8.7280057e-78 | F18: 0.90288625 | G18: 0.97276448 | H18: 0.90288625 | I18: 0.97276448

Sheet max_dd
A1: Date | B1: =表格1_[[#Headers],[中港基金]] -> 中港基金 | C1: =表格1_[[#Headers],[亞洲股票基金]] -> 亞洲股票基金 | D1: =表格1_[[#Headers],[亞洲債券基金]] -> 亞洲債券基金 | E1: =表格1_[[#Headers],[核心累積基金]] -> 核心累積基金 | F1: =表格1_[[#Headers],[增長組合]] -> 增長組合 | G1: =表格1_[[#Headers],[北美股票基金]] -> 北美股票基金 | H1: =表格1_[[#Headers],[基金經理精選退休基金]] -> 基金經理精選退休基金 | I1: =表格1_[[#Headers],[美洲基金]] -> 美洲基金 | J1: =表格1_[[#Headers],[強積金保守基金]] -> 強積金保守基金 | K1: =表格1_[[#Headers],[均衡組合]] -> 均衡組合
A2: 42856 | B2: =(mpf_monthly_price!B3-MAX(mpf_monthly_price!B$2:B3))/MAX(mpf_monthly_price!B$2:B3) -> 0 | C2: =(mpf_monthly_price!C3-MAX(mpf_monthly_price!C$2:C3))/MAX(mpf_monthly_price!C$2:C3) -> 0 | D2: =(mpf_monthly_price!D3-MAX(mpf_monthly_price!D$2:D3))/MAX(mpf_monthly_price!D$2:D3) -> 0 | E2: =(mpf_monthly_price!E3-MAX(mpf_monthly_price!E$2:E3))/MAX(mpf_monthly_price!E$2:E3) -> 0 | F2: =(mpf_monthly_price!F3-MAX(mpf_monthly_price!F$2:F3))/MAX(mpf_monthly_price!F$2:F3) -> 0 | G2: =(mpf_monthly_price!G3-MAX(mpf_monthly_price!G$2:G3))/MAX(mpf_monthly_price!G$2:G3) -> 0 | H2: =(mpf_monthly_price!H3-MAX(mpf_monthly_price!H$2:H3))/MAX(mpf_monthly_price!H$2:H3) -> 0 | I2: =(mpf_monthly_price!I3-MAX(mpf_monthly_price!I$2:I3))/MAX(mpf_monthly_price!I$2:I3) -> 0 | ... K2: =(mpf_monthly_price!K3-MAX(mpf_monthly_price!K$2:K3))/MAX(mpf_monthly_price!K$2:K3) -> 0
A3: 42887 | B3: =(mpf_monthly_price!B4-MAX(mpf_monthly_price!B$2:B4))/MAX(mpf_monthly_price!B$2:B4) -> 0 | C3: =(mpf_monthly_price!C4-MAX(mpf_monthly_price!C$2:C4))/MAX(mpf_monthly_price!C$2:C4) -> 0 | D3: =(mpf_monthly_price!D4-MAX(mpf_monthly_price!D$2:D4))/MAX(mpf_monthly_price!D$2:D4) -> 0 | E3: =(mpf_monthly_price!E4-MAX(mpf_monthly_price!E$2:E4))/MAX(mpf_monthly_price!E$2:E4) -> -0.0019514099 | F3: =(mpf_monthly_price!F4-MAX(mpf_monthly_price!F$2:F4))/MAX(mpf_monthly_price!F$2:F4) -> 0 | G3: =(mpf_monthly_price!G4-MAX(mpf_monthly_price!G$2:G4))/MAX(mpf_monthly_price!G$2:G4) -> -0.0024454661 | H3: =(mpf_monthly_price!H4-MAX(mpf_monthly_price!H$2:H4))/MAX(mpf_monthly_price!H$2:H4) -> 0 | I3: =(mpf_monthly_price!I4-MAX(mpf_monthly_price!I$2:I4))/MAX(mpf_monthly_price!I$2:I4) -> -0.00051232424 | ... K3: =(mpf_monthly_price!K4-MAX(mpf_monthly_price!K$2:K4))/MAX(mpf_monthly_price!K$2:K4) -> 0
A4: 42917 | B4: =(mpf_monthly_price!B5-MAX(mpf_monthly_price!B$2:B5))/MAX(mpf_monthly_price!B$2:B5) -> 0 | C4: =(mpf_monthly_price!C5-MAX(mpf_monthly_price!C$2:C5))/MAX(mpf_monthly_price!C$2:C5) -> 0 | D4: =(mpf_monthly_price!D5-MAX(mpf_monthly_price!D$2:D5))/MAX(mpf_monthly_price!D$2:D5) -> 0 | E4: =(mpf_monthly_price!E5-MAX(mpf_monthly_price!E$2:E5))/MAX(mpf_monthly_price!E$2:E5) -> 0 | F4: =(mpf_monthly_price!F5-MAX(mpf_monthly_price!F$2:F5))/MAX(mpf_monthly_price!F$2:F5) -> 0 | G4: =(mpf_monthly_price!G5-MAX(mpf_monthly_price!G$2:G5))/MAX(mpf_monthly_price!G$2:G5) -> 0 | H4: =(mpf_monthly_price!H5-MAX(mpf_monthly_price!H$2:H5))/MAX(mpf_monthly_price!H$2:H5) -> 0 | I4: =(mpf_monthly_price!I5-MAX(mpf_monthly_price!I$2:I5))/MAX(mpf_monthly_price!I$2:I5) -> 0 | ... K4: =(mpf_monthly_price!K5-MAX(mpf_monthly_price!K$2:K5))/MAX(mpf_monthly_price!K$2:K5) -> 0
A5: 42948 | B5: =(mpf_monthly_price!B6-MAX(mpf_monthly_price!B$2:B6))/MAX(mpf_monthly_price!B$2:B6) -> 0 | C5: =(mpf_monthly_price!C6-MAX(mpf_monthly_price!C$2:C6))/MAX(mpf_monthly_price!C$2:C6) -> -0.011136421 | D5: =(mpf_monthly_price!D6-MAX(mpf_monthly_price!D$2:D6))/MAX(mpf_monthly_price!D$2:D6) -> 0 | E5: =(mpf_monthly_price!E6-MAX(mpf_monthly_price!E$2:E6))/MAX(mpf_monthly_price!E$2:E6) -> 0 | F5: =(mpf_monthly_price!F6-MAX(mpf_monthly_price!F$2:F6))/MAX(mpf_monthly_price!F$2:F6) -> 0 | G5: =(mpf_monthly_price!G6-MAX(mpf_monthly_price!G$2:G6))/MAX(mpf_monthly_price!G$2:G6) -> -0.0025641026 | H5: =(mpf_monthly_price!H6-MAX(mpf_monthly_price!H$2:H6))/MAX(mpf_monthly_price!H$2:H6) -> 0 | I5: =(mpf_monthly_price!I6-MAX(mpf_monthly_price!I$2:I6))/MAX(mpf_monthly_price!I$2:I6) -> 0 | ... K5: =(mpf_monthly_price!K6-MAX(mpf_monthly_price!K$2:K6))/MAX(mpf_monthly_price!K$2:K6) -> 0
A6: 42979 | B6: =(mpf_monthly_price!B7-MAX(mpf_monthly_price!B$2:B7))/MAX(mpf_monthly_price!B$2:B7) -> -0.016586538 | C6: =(mpf_monthly_price!C7-MAX(mpf_monthly_price!C$2:C7))/MAX(mpf_monthly_price!C$2:C7) -> -0.026828651 | D6: =(mpf_monthly_price!D7-MAX(mpf_monthly_price!D$2:D7))/MAX(mpf_monthly_price!D$2:D7) -> -0.009078277 | E6: =(mpf_monthly_price!E7-MAX(mpf_monthly_price!E$2:E7))/MAX(mpf_monthly_price!E$2:E7) -> 0 | F6: =(mpf_monthly_price!F7-MAX(mpf_monthly_price!F$2:F7))/MAX(mpf_monthly_price!F$2:F7) -> 0 | G6: =(mpf_monthly_price!G7-MAX(mpf_monthly_price!G$2:G7))/MAX(mpf_monthly_price!G$2:G7) -> 0 | H6: =(mpf_monthly_price!H7-MAX(mpf_monthly_price!H$2:H7))/MAX(mpf_monthly_price!H$2:H7) -> 0 | I6: =(mpf_monthly_price!I7-MAX(mpf_monthly_price!I$2:I7))/MAX(mpf_monthly_price!I$2:I7) -> 0 | ... K6: =(mpf_monthly_price!K7-MAX(mpf_monthly_price!K$2:K7))/MAX(mpf_monthly_price!K$2:K7) -> 0
A7: 43009 | B7: =(mpf_monthly_price!B8-MAX(mpf_monthly_price!B$2:B8))/MAX(mpf_monthly_price!B$2:B8) -> 0 | C7: =(mpf_monthly_price!C8-MAX(mpf_monthly_price!C$2:C8))/MAX(mpf_monthly_price!C$2:C8) -> 0 | D7: =(mpf_monthly_price!D8-MAX(mpf_monthly_price!D$2:D8))/MAX(mpf_monthly_price!D$2:D8) -> -0.013061603 | E7: =(mpf_monthly_price!E8-MAX(mpf_monthly_price!E$2:E8))/MAX(mpf_monthly_price!E$2:E8) -> 0 | F7: =(mpf_monthly_price!F8-MAX(mpf_monthly_price!F$2:F8))/MAX(mpf_monthly_price!F$2:F8) -> 0 | G7: =(mpf_monthly_price!G8-MAX(mpf_monthly_price!G$2:G8))/MAX(mpf_monthly_price!G$2:G8) -> 0 | H7: =(mpf_monthly_price!H8-MAX(mpf_monthly_price!H$2:H8))/MAX(mpf_monthly_price!H$2:H8) -> 0 | I7: =(mpf_monthly_price!I8-MAX(mpf_monthly_price!I$2:I8))/MAX(mpf_monthly_price!I$2:I8) -> 0 | ... K7: =(mpf_monthly_price!K8-MAX(mpf_monthly_price!K$2:K8))/MAX(mpf_monthly_price!K$2:K8) -> 0
A8: 43040 | B8: =(mpf_monthly_price!B9-MAX(mpf_monthly_price!B$2:B9))/MAX(mpf_monthly_price!B$2:B9) -> 0 | C8: =(mpf_monthly_price!C9-MAX(mpf_monthly_price!C$2:C9))/MAX(mpf_monthly_price!C$2:C9) -> -0.017376337 | D8: =(mpf_monthly_price!D9-MAX(mpf_monthly_price!D$2:D9))/MAX(mpf_monthly_price!D$2:D9) -> -0.0025011579 | E8: =(mpf_monthly_price!E9-MAX(mpf_monthly_price!E$2:E9))/MAX(mpf_monthly_price!E$2:E9) -> 0 | F8: =(mpf_monthly_price!F9-MAX(mpf_monthly_price!F$2:F9))/MAX(mpf_monthly_price!F$2:F9) -> 0 | G8: =(mpf_monthly_price!G9-MAX(mpf_monthly_price!G$2:G9))/MAX(mpf_monthly_price!G$2:G9) -> 0 | H8: =(mpf_monthly_price!H9-MAX(mpf_monthly_price!H$2:H9))/MAX(mpf_monthly_price!H$2:H9) -> 0 | I8: =(mpf_monthly_price!I9-MAX(mpf_monthly_price!I$2:I9))/MAX(mpf_monthly_price!I$2:I9) -> 0 | ... K8: =(mpf_monthly_price!K9-MAX(mpf_monthly_price!K$2:K9))/MAX(mpf_monthly_price!K$2:K9) -> 0
A9: 43070 | B9: =(mpf_monthly_price!B10-MAX(mpf_monthly_price!B$2:B10))/MAX(mpf_monthly_price!B$2:B10) -> 0 | C9: =(mpf_monthly_price!C10-MAX(mpf_monthly_price!C$2:C10))/MAX(mpf_monthly_price!C$2:C10) -> 0 | D9: =(mpf_monthly_price!D10-MAX(mpf_monthly_price!D$2:D10))/MAX(mpf_monthly_price!D$2:D10) -> 0 | E9: =(mpf_monthly_price!E10-MAX(mpf_monthly_price!E$2:E10))/MAX(mpf_monthly_price!E$2:E10) -> 0 | F9: =(mpf_monthly_price!F10-MAX(mpf_monthly_price!F$2:F10))/MAX(mpf_monthly_price!F$2:F10) -> 0 | G9: =(mpf_monthly_price!G10-MAX(mpf_monthly_price!G$2:G10))/MAX(mpf_monthly_price!G$2:G10) -> 0 | H9: =(mpf_monthly_price!H10-MAX(mpf_monthly_price!H$2:H10))/MAX(mpf_monthly_price!H$2:H10) -> 0 | I9: =(mpf_monthly_price!I10-MAX(mpf_monthly_price!I$2:I10))/MAX(mpf_monthly_price!I$2:I10) -> 0 | ... K9: =(mpf_monthly_price!K10-MAX(mpf_monthly_price!K$2:K10))/MAX(mpf_monthly_price!K$2:K10) -> 0
A10: 43101 | B10: =(mpf_monthly_price!B11-MAX(mpf_monthly_price!B$2:B11))/MAX(mpf_monthly_price!B$2:B11) -> 0 | C10: =(mpf_monthly_price!C11-MAX(mpf_monthly_price!C$2:C11))/MAX(mpf_monthly_price!C$2:C11) -> 0 | D10: =(mpf_monthly_price!D11-MAX(mpf_monthly_price!D$2:D11))/MAX(mpf_monthly_price!D$2:D11) -> 0 | E10: =(mpf_monthly_price!E11-MAX(mpf_monthly_price!E$2:E11))/MAX(mpf_monthly_price!E$2:E11) -> 0 | F10: =(mpf_monthly_price!F11-MAX(mpf_monthly_price!F$2:F11))/MAX(mpf_monthly_price!F$2:F11) -> 0 | G10: =(mpf_monthly_price!G11-MAX(mpf_monthly_price!G$2:G11))/MAX(mpf_monthly_price!G$2:G11) -> 0 | H10: =(mpf_monthly_price!H11-MAX(mpf_monthly_price!H$2:H11))/MAX(mpf_monthly_price!H$2:H11) -> 0 | I10: =(mpf_monthly_price!I11-MAX(mpf_monthly_price!I$2:I11))/MAX(mpf_monthly_price!I$2:I11) -> 0 | ... K10: =(mpf_monthly_price!K11-MAX(mpf_monthly_price!K$2:K11))/MAX(mpf_monthly_price!K$2:K11) -> 0
A11: 43132 | B11: =(mpf_monthly_price!B12-MAX(mpf_monthly_price!B$2:B12))/MAX(mpf_monthly_price!B$2:B12) -> -0.054530545 | C11: =(mpf_monthly_price!C12-MAX(mpf_monthly_price!C$2:C12))/MAX(mpf_monthly_price!C$2:C12) -> -0.041006776 | D11: =(mpf_monthly_price!D12-MAX(mpf_monthly_price!D$2:D12))/MAX(mpf_monthly_price!D$2:D12) -> -0.0089424218 | E11: =(mpf_monthly_price!E12-MAX(mpf_monthly_price!E$2:E12))/MAX(mpf_monthly_price!E$2:E12) -> -0.030470421 | F11: =(mpf_monthly_price!F12-MAX(mpf_monthly_price!F$2:F12))/MAX(mpf_monthly_price!F$2:F12) -> -0.049873783 | G11: =(mpf_monthly_price!G12-MAX(mpf_monthly_price!G$2:G12))/MAX(mpf_monthly_price!G$2:G12) -> -0.048300088 | H11: =(mpf_monthly_price!H12-MAX(mpf_monthly_price!H$2:H12))/MAX(mpf_monthly_price!H$2:H12) -> -0.044617274 | I11: =(mpf_monthly_price!I12-MAX(mpf_monthly_price!I$2:I12))/MAX(mpf_monthly_price!I$2:I12) -> -0.049058592 | ... K11: =(mpf_monthly_price!K12-MAX(mpf_monthly_price!K$2:K12))/MAX(mpf_monthly_price!K$2:K12) -> -0.030335619
A12: 43160 | B12: =(mpf_monthly_price!B13-MAX(mpf_monthly_price!B$2:B13))/MAX(mpf_monthly_price!B$2:B13) -> -0.083640836 | C12: =(mpf_monthly_price!C13-MAX(mpf_monthly_price!C$2:C13))/MAX(mpf_monthly_price!C$2:C13) -> -0.056456922 | D12: =(mpf_monthly_price!D13-MAX(mpf_monthly_price!D$2:D13))/MAX(mpf_monthly_price!D$2:D13) -> -0.001824984 | E12: =(mpf_monthly_price!E13-MAX(mpf_monthly_price!E$2:E13))/MAX(mpf_monthly_price!E$2:E13) -> -0.032252316 | F12: =(mpf_monthly_price!F13-MAX(mpf_monthly_price!F$2:F13))/MAX(mpf_monthly_price!F$2:F13) -> -0.065957447 | G12: =(mpf_monthly_price!G13-MAX(mpf_monthly_price!G$2:G13))/MAX(mpf_monthly_price!G$2:G13) -> -0.062267386 | H12: =(mpf_monthly_price!H13-MAX(mpf_monthly_price!H$2:H13))/MAX(mpf_monthly_price!H$2:H13) -> -0.058739255 | I12: =(mpf_monthly_price!I13-MAX(mpf_monthly_price!I$2:I13))/MAX(mpf_monthly_price!I$2:I13) -> -0.058352896 | ... K12: =(mpf_monthly_price!K13-MAX(mpf_monthly_price!K$2:K13))/MAX(mpf_monthly_price!K$2:K13) -> -0.037280997
A13: 43191 | B13: =(mpf_monthly_price!B14-MAX(mpf_monthly_price!B$2:B14))/MAX(mpf_monthly_price!B$2:B14) -> -0.060168102 | C13: =(mpf_monthly_price!C14-MAX(mpf_monthly_price!C$2:C14))/MAX(mpf_monthly_price!C$2:C14) -> -0.034269119 | D13: =(mpf_monthly_price!D14-MAX(mpf_monthly_price!D$2:D14))/MAX(mpf_monthly_price!D$2:D14) -> -0.015877361 | E13: =(mpf_monthly_price!E14-MAX(mpf_monthly_price!E$2:E14))/MAX(mpf_monthly_price!E$2:E14) -> -0.028866714 | F13: =(mpf_monthly_price!F14-MAX(mpf_monthly_price!F$2:F14))/MAX(mpf_monthly_price!F$2:F14) -> -0.056148576 | G13: =(mpf_monthly_price!G14-MAX(mpf_monthly_price!G$2:G14))/MAX(mpf_monthly_price!G$2:G14) -> -0.053652825 | H13: =(mpf_monthly_price!H14-MAX(mpf_monthly_price!H$2:H14))/MAX(mpf_monthly_price!H$2:H14) -> -0.051064265 | I13: =(mpf_monthly_price!I14-MAX(mpf_monthly_price!I$2:I14))/MAX(mpf_monthly_price!I$2:I14) -> -0.061610693 | ... K13: =(mpf_monthly_price!K14-MAX(mpf_monthly_price!K$2:K14))/MAX(mpf_monthly_price!K$2:K14) -> -0.036922525
... A108: 46082 | B108: =(mpf_monthly_price!B109-MAX(mpf_monthly_price!B$2:B109))/MAX(mpf_monthly_price!B$2:B109) -> -0.077900779 | C108: =(mpf_monthly_price!C109-MAX(mpf_monthly_price!C$2:C109))/MAX(mpf_monthly_price!C$2:C109) -> -0.076766447 | D108: =(mpf_monthly_price!D109-MAX(mpf_monthly_price!D$2:D109))/MAX(mpf_monthly_price!D$2:D109) -> -0.023501667 | E108: =(mpf_monthly_price!E109-MAX(mpf_monthly_price!E$2:E109))/MAX(mpf_monthly_price!E$2:E109) -> -0.034810476 | F108: =(mpf_monthly_price!F109-MAX(mpf_monthly_price!F$2:F109))/MAX(mpf_monthly_price!F$2:F109) -> -0.048698144 | G108: =(mpf_monthly_price!G109-MAX(mpf_monthly_price!G$2:G109))/MAX(mpf_monthly_price!G$2:G109) -> -0.058652586 | H108: =(mpf_monthly_price!H109-MAX(mpf_monthly_price!H$2:H109))/MAX(mpf_monthly_price!H$2:H109) -> -0.040720406 | I108: =(mpf_monthly_price!I109-MAX(mpf_monthly_price!I$2:I109))/MAX(mpf_monthly_price!I$2:I109) -> -0.055899673 | ... K108: =(mpf_monthly_price!K109-MAX(mpf_monthly_price!K$2:K109))/MAX(mpf_monthly_price!K$2:K109) -> -0.034567992

Sheet downside
A1: Date | B1: =表格1_[[#Headers],[中港基金]] -> 中港基金 | C1: =表格1_[[#Headers],[亞洲股票基金]] -> 亞洲股票基金 | D1: =表格1_[[#Headers],[亞洲債券基金]] -> 亞洲債券基金 | E1: =表格1_[[#Headers],[核心累積基金]] -> 核心累積基金 | F1: =表格1_[[#Headers],[增長組合]] -> 增長組合 | G1: =表格1_[[#Headers],[北美股票基金]] -> 北美股票基金 | H1: =表格1_[[#Headers],[基金經理精選退休基金]] -> 基金經理精選退休基金 | I1: =表格1_[[#Headers],[美洲基金]] -> 美洲基金 | J1: =表格1_[[#Headers],[強積金保守基金]] -> 強積金保守基金 | K1: =表格1_[[#Headers],[均衡組合]] -> 均衡組合
A3: 42887 | B3: =IF(mpf_monthly_return!B2 < 0, mpf_monthly_return!B2, 0) -> 0 | C3: =IF(mpf_monthly_return!C2 < 0, mpf_monthly_return!C2, 0) -> 0 | D3: =IF(mpf_monthly_return!D2 < 0, mpf_monthly_return!D2, 0) -> 0 | E3: =IF(mpf_monthly_return!E2 < 0, mpf_monthly_return!E2, 0) -> 0 | F3: =IF(mpf_monthly_return!F2 < 0, mpf_monthly_return!F2, 0) -> 0 | G3: =IF(mpf_monthly_return!G2 < 0, mpf_monthly_return!G2, 0) -> 0 | H3: =IF(mpf_monthly_return!H2 < 0, mpf_monthly_return!H2, 0) -> 0 | I3: =IF(mpf_monthly_return!I2 < 0, mpf_monthly_return!I2, 0) -> 0 | ... K3: =IF(mpf_monthly_return!K2 < 0, mpf_monthly_return!K2, 0) -> 0
A4: 42917 | B4: =IF(mpf_monthly_return!B3 < 0, mpf_monthly_return!B3, 0) -> 0 | C4: =IF(mpf_monthly_return!C3 < 0, mpf_monthly_return!C3, 0) -> 0 | D4: =IF(mpf_monthly_return!D3 < 0, mpf_monthly_return!D3, 0) -> 0 | E4: =IF(mpf_monthly_return!E3 < 0, mpf_monthly_return!E3, 0) -> -0.0019533164 | F4: =IF(mpf_monthly_return!F3 < 0, mpf_monthly_return!F3, 0) -> 0 | G4: =IF(mpf_monthly_return!G3 < 0, mpf_monthly_return!G3, 0) -> -0.0024484611 | H4: =IF(mpf_monthly_return!H3 < 0, mpf_monthly_return!H3, 0) -> 0 | I4: =IF(mpf_monthly_return!I3 < 0, mpf_monthly_return!I3, 0) -> -0.00051245553 | ... K4: =IF(mpf_monthly_return!K3 < 0, mpf_monthly_return!K3, 0) -> 0
A5: 42948 | B5: =IF(mpf_monthly_return!B4 < 0, mpf_monthly_return!B4, 0) -> 0 | C5: =IF(mpf_monthly_return!C4 < 0, mpf_monthly_return!C4, 0) -> 0 | D5: =IF(mpf_monthly_return!D4 < 0, mpf_monthly_return!D4, 0) -> 0 | E5: =IF(mpf_monthly_return!E4 < 0, mpf_monthly_return!E4, 0) -> 0 | F5: =IF(mpf_monthly_return!F4 < 0, mpf_monthly_return!F4, 0) -> 0 | G5: =IF(mpf_monthly_return!G4 < 0, mpf_monthly_return!G4, 0) -> 0 | H5: =IF(mpf_monthly_return!H4 < 0, mpf_monthly_return!H4, 0) -> 0 | I5: =IF(mpf_monthly_return!I4 < 0, mpf_monthly_return!I4, 0) -> 0 | ... K5: =IF(mpf_monthly_return!K4 < 0, mpf_monthly_return!K4, 0) -> 0
A6: 42979 | B6: =IF(mpf_monthly_return!B5 < 0, mpf_monthly_return!B5, 0) -> 0 | C6: =IF(mpf_monthly_return!C5 < 0, mpf_monthly_return!C5, 0) -> -0.011198895 | D6: =IF(mpf_monthly_return!D5 < 0, mpf_monthly_return!D5, 0) -> 0 | E6: =IF(mpf_monthly_return!E5 < 0, mpf_monthly_return!E5, 0) -> 0 | F6: =IF(mpf_monthly_return!F5 < 0, mpf_monthly_return!F5, 0) -> 0 | G6: =IF(mpf_monthly_return!G5 < 0, mpf_monthly_return!G5, 0) -> -0.0025673955 | H6: =IF(mpf_monthly_return!H5 < 0, mpf_monthly_return!H5, 0) -> 0 | I6: =IF(mpf_monthly_return!I5 < 0, mpf_monthly_return!I5, 0) -> 0 | ... K6: =IF(mpf_monthly_return!K5 < 0, mpf_monthly_return!K5, 0) -> 0
A7: 43009 | B7: =IF(mpf_monthly_return!B6 < 0, mpf_monthly_return!B6, 0) -> -0.016725635 | C7: =IF(mpf_monthly_return!C6 < 0, mpf_monthly_return!C6, 0) -> -0.015996213 | D7: =IF(mpf_monthly_return!D6 < 0, mpf_monthly_return!D6, 0) -> -0.0091197356 | E7: =IF(mpf_monthly_return!E6 < 0, mpf_monthly_return!E6, 0) -> 0 | F7: =IF(mpf_monthly_return!F6 < 0, mpf_monthly_return!F6, 0) -> 0 | G7: =IF(mpf_monthly_return!G6 < 0, mpf_monthly_return!G6, 0) -> 0 | H7: =IF(mpf_monthly_return!H6 < 0, mpf_monthly_return!H6, 0) -> 0 | I7: =IF(mpf_monthly_return!I6 < 0, mpf_monthly_return!I6, 0) -> 0 | ... K7: =IF(mpf_monthly_return!K6 < 0, mpf_monthly_return!K6, 0) -> 0
A8: 43040 | B8: =IF(mpf_monthly_return!B7 < 0, mpf_monthly_return!B7, 0) -> 0 | C8: =IF(mpf_monthly_return!C7 < 0, mpf_monthly_return!C7, 0) -> 0 | D8: =IF(mpf_monthly_return!D7 < 0, mpf_monthly_return!D7, 0) -> -0.0040279198 | E8: =IF(mpf_monthly_return!E7 < 0, mpf_monthly_return!E7, 0) -> 0 | F8: =IF(mpf_monthly_return!F7 < 0, mpf_monthly_return!F7, 0) -> 0 | G8: =IF(mpf_monthly_return!G7 < 0, mpf_monthly_return!G7, 0) -> 0 | H8: =IF(mpf_monthly_return!H7 < 0, mpf_monthly_return!H7, 0) -> 0 | I8: =IF(mpf_monthly_return!I7 < 0, mpf_monthly_return!I7, 0) -> 0 | ... K8: =IF(mpf_monthly_return!K7 < 0, mpf_monthly_return!K7, 0) -> 0
A9: 43070 | B9: =IF(mpf_monthly_return!B8 < 0, mpf_monthly_return!B8, 0) -> 0 | C9: =IF(mpf_monthly_return!C8 < 0, mpf_monthly_return!C8, 0) -> -0.017529078 | D9: =IF(mpf_monthly_return!D8 < 0, mpf_monthly_return!D8, 0) -> 0 | E9: =IF(mpf_monthly_return!E8 < 0, mpf_monthly_return!E8, 0) -> 0 | F9: =IF(mpf_monthly_return!F8 < 0, mpf_monthly_return!F8, 0) -> 0 | G9: =IF(mpf_monthly_return!G8 < 0, mpf_monthly_return!G8, 0) -> 0 | H9: =IF(mpf_monthly_return!H8 < 0, mpf_monthly_return!H8, 0) -> 0 | I9: =IF(mpf_monthly_return!I8 < 0, mpf_monthly_return!I8, 0) -> 0 | ... K9: =IF(mpf_monthly_return!K8 < 0, mpf_monthly_return!K8, 0) -> 0
A10: 43101 | B10: =IF(mpf_monthly_return!B9 < 0, mpf_monthly_return!B9, 0) -> 0 | C10: =IF(mpf_monthly_return!C9 < 0, mpf_monthly_return!C9, 0) -> 0 | D10: =IF(mpf_monthly_return!D9 < 0, mpf_monthly_return!D9, 0) -> 0 | E10: =IF(mpf_monthly_return!E9 < 0, mpf_monthly_return!E9, 0) -> 0 | F10: =IF(mpf_monthly_return!F9 < 0, mpf_monthly_return!F9, 0) -> 0 | G10: =IF(mpf_monthly_return!G9 < 0, mpf_monthly_return!G9, 0) -> 0 | H10: =IF(mpf_monthly_return!H9 < 0, mpf_monthly_return!H9, 0) -> 0 | I10: =IF(mpf_monthly_return!I9 < 0, mpf_monthly_return!I9, 0) -> 0 | ... K10: =IF(mpf_monthly_return!K9 < 0, mpf_monthly_return!K9, 0) -> 0
A11: 43132 | B11: =IF(mpf_monthly_return!B10 < 0, mpf_monthly_return!B10, 0) -> 0 | C11: =IF(mpf_monthly_return!C10 < 0, mpf_monthly_return!C10, 0) -> 0 | D11: =IF(mpf_monthly_return!D10 < 0, mpf_monthly_return!D10, 0) -> 0 | E11: =IF(mpf_monthly_return!E10 < 0, mpf_monthly_return!E10, 0) -> 0 | F11: =IF(mpf_monthly_return!F10 < 0, mpf_monthly_return!F10, 0) -> 0 | G11: =IF(mpf_monthly_return!G10 < 0, mpf_monthly_return!G10, 0) -> 0 | H11: =IF(mpf_monthly_return!H10 < 0, mpf_monthly_return!H10, 0) -> 0 | I11: =IF(mpf_monthly_return!I10 < 0, mpf_monthly_return!I10, 0) -> 0 | ... K11: =IF(mpf_monthly_return!K10 < 0, mpf_monthly_return!K10, 0) -> 0
A12: 43160 | B12: =IF(mpf_monthly_return!B11 < 0, mpf_monthly_return!B11, 0) -> -0.056073697 | C12: =IF(mpf_monthly_return!C11 < 0, mpf_monthly_return!C11, 0) -> -0.04187127 | D12: =IF(mpf_monthly_return!D11 < 0, mpf_monthly_return!D11, 0) -> -0.0089826452 | E12: =IF(mpf_monthly_return!E11 < 0, mpf_monthly_return!E11, 0) -> -0.030944295 | F12: =IF(mpf_monthly_return!F11 < 0, mpf_monthly_return!F11, 0) -> -0.051160443 | G12: =IF(mpf_monthly_return!G11 < 0, mpf_monthly_return!G11, 0) -> -0.049505512 | H12: =IF(mpf_monthly_return!H11 < 0, mpf_monthly_return!H11, 0) -> -0.045643258 | I12: =IF(mpf_monthly_return!I11 < 0, mpf_monthly_return!I11, 0) -> -0.05030283 | ... K12: =IF(mpf_monthly_return!K11 < 0, mpf_monthly_return!K11, 0) -> -0.030805266
A13: 43191 | B13: =IF(mpf_monthly_return!B12 < 0, mpf_monthly_return!B12, 0) -> -0.031273194 | C13: =IF(mpf_monthly_return!C12 < 0, mpf_monthly_return!C12, 0) -> -0.016241987 | D13: =IF(mpf_monthly_return!D12 < 0, mpf_monthly_return!D12, 0) -> 0 | E13: =IF(mpf_monthly_return!E12 < 0, mpf_monthly_return!E12, 0) -> -0.0018395885 | F13: =IF(mpf_monthly_return!F12 < 0, mpf_monthly_return!F12, 0) -> -0.017072839 | G13: =IF(mpf_monthly_return!G12 < 0, mpf_monthly_return!G12, 0) -> -0.014784918 | H13: =IF(mpf_monthly_return!H12 < 0, mpf_monthly_return!H12, 0) -> -0.014891826 | I13: =IF(mpf_monthly_return!I12 < 0, mpf_monthly_return!I12, 0) -> -0.0098218692 | ... K13: =IF(mpf_monthly_return!K12 < 0, mpf_monthly_return!K12, 0) -> -0.0071884368
A14: 43221 | B14: =IF(mpf_monthly_return!B13 < 0, mpf_monthly_return!B13, 0) -> 0 | C14: =IF(mpf_monthly_return!C13 < 0, mpf_monthly_return!C13, 0) -> 0 | D14: =IF(mpf_monthly_return!D13 < 0, mpf_monthly_return!D13, 0) -> -0.014178105 | E14: =IF(mpf_monthly_return!E13 < 0, mpf_monthly_return!E13, 0) -> 0 | F14: =IF(mpf_monthly_return!F13 < 0, mpf_monthly_return!F13, 0) -> 0 | G14: =IF(mpf_monthly_return!G13 < 0, mpf_monthly_return!G13, 0) -> 0 | H14: =IF(mpf_monthly_return!H13 < 0, mpf_monthly_return!H13, 0) -> 0 | I14: =IF(mpf_monthly_return!I13 < 0, mpf_monthly_return!I13, 0) -> -0.003465678 | ... K14: =IF(mpf_monthly_return!K13 < 0, mpf_monthly_return!K13, 0) -> 0
... A109: 46113 | B109: =IF(mpf_monthly_return!B108 < 0, mpf_monthly_return!B108, 0) -> -0.029085988 | C109: =IF(mpf_monthly_return!C108 < 0, mpf_monthly_return!C108, 0) -> -0.079873039 | D109: =IF(mpf_monthly_return!D108 < 0, mpf_monthly_return!D108, 0) -> -0.012907675 | E109: =IF(mpf_monthly_return!E108 < 0, mpf_monthly_return!E108, 0) -> -0.035430799 | F109: =IF(mpf_monthly_return!F108 < 0, mpf_monthly_return!F108, 0) -> -0.049923858 | G109: =IF(mpf_monthly_return!G108 < 0, mpf_monthly_return!G108, 0) -> -0.046692424 | H109: =IF(mpf_monthly_return!H108 < 0, mpf_monthly_return!H108, 0) -> -0.041572699 | I109: =IF(mpf_monthly_return!I108 < 0, mpf_monthly_return!I108, 0) -> -0.044328211 | ... K109: =IF(mpf_monthly_return!K108 < 0, mpf_monthly_return!K108, 0) -> -0.035179601

Sheet mpf_daily_price
A1: Date | B1: 中港基金 | C1: 亞洲股票基金 | D1: 亞洲債券基金 | E1: 核心累積基金 | F1: 增長組合 | G1: 北美股票基金 | H1: 基金經理精選退休基金 | I1: 美洲基金 | J1: 強積金保守基金 | K1: 均衡組合
A2: 42859 | B2: 144.67 | C2: 217.16 | D2: 104.38 | E2: 1.0136 | F2: 223.3 | G2: 200.72 | H2: 161.31 | I2: 173.66 | J2: 111.62 | K2: 195.79
A3: 42860 | B3: 143.01 | C3: 216.27 | D3: 104.28 | E3: 1.0164 | F3: 223.04 | G3: 201.96 | H3: 161.19 | I3: 174.8 | J3: 111.62 | K3: 195.7
A4: 42861 | B4: 143.01 | C4: 216.27 | D4: 104.28 | E4: 1.0164 | F4: 223.04 | G4: 201.96 | H4: 161.19 | I4: 174.8 | J4: 111.62 | K4: 195.7
A5: 42862 | B5: 143.01 | C5: 216.27 | D5: 104.28 | E5: 1.0164 | F5: 223.04 | G5: 201.96 | H5: 161.19 | I5: 174.8 | J5: 111.62 | K5: 195.7
A6: 42863 | B6: 143.66 | C6: 218.84 | D6: 104.28 | E6: 1.0166 | F6: 224 | G6: 202.15 | H6: 161.97 | I6: 174.39 | J6: 111.62 | K6: 196.2
A7: 42864 | B7: 145.41 | C7: 218.18 | D7: 104.18 | E7: 1.0152 | F7: 224.55 | G7: 201.83 | H7: 162.09 | I7: 174.62 | J7: 111.62 | K7: 196.22
A8: 42865 | B8: 146.09 | C8: 217.8 | D8: 104.18 | E8: 1.0166 | F8: 224.95 | G8: 202.19 | H8: 162.39 | I8: 175.42 | J8: 111.62 | K8: 196.51
A9: 42866 | B9: 146.89 | C9: 219.26 | D9: 104.27 | E9: 1.016 | F9: 225.02 | G9: 201.68 | H9: 162.45 | I9: 175.38 | J9: 111.62 | K9: 196.54
A10: 42867 | B10: 147.21 | C10: 218.51 | D10: 104.46 | E10: 1.0179 | F10: 225.1 | G10: 201.24 | H10: 162.39 | I10: 175.72 | J10: 111.62 | K10: 196.7
A11: 42868 | B11: 147.21 | C11: 218.51 | D11: 104.46 | E11: 1.0179 | F11: 225.1 | G11: 201.24 | H11: 162.39 | I11: 175.72 | J11: 111.62 | K11: 196.7
A12: 42869 | B12: 147.21 | C12: 218.51 | D12: 104.46 | E12: 1.0179 | F12: 225.1 | G12: 201.24 | H12: 162.39 | I12: 175.72 | J12: 111.62 | K12: 196.7
A13: 42870 | B13: 148.77 | C13: 219.34 | D13: 104.73 | E13: 1.0198 | F13: 226.17 | G13: 201.97 | H13: 162.92 | I13: 176.72 | J13: 111.62 | K13: 197.13
... A3200: 46140 | B3200: 182.89 | C3200: 543.31 | D3200: 120.73 | E3200: 1.8243 | F3200: 412.71 | G3200: 542.03 | H3200: 239.84 | I3200: 469.62 | J3200: 125.92 | K3200: 269.88

Sheet mpf_monthly_price
A1: Date | B1: 中港基金 | C1: 亞洲股票基金 | D1: 亞洲債券基金 | E1: 核心累積基金 | F1: 增長組合 | G1: 北美股票基金 | H1: 基金經理精選退休基金 | I1: 美洲基金 | J1: 強積金保守基金 | K1: 均衡組合
A2: 42859 | B2: 144.61 | C2: 216.84 | D2: 104.39 | E2: 1.0114 | F2: 222.43 | G2: 200.95 | H2: 161.12 | I2: 173.67 | J2: 111.62 | K2: 195.66
A3: 42887 | B3: 151.11 | C3: 220.01 | D3: 105.71 | E3: 1.0249 | F3: 229.67 | G3: 204.46 | H3: 165.13 | I3: 175.67 | J3: 111.63 | K3: 199.45
A4: 42917 | B4: 151.94 | C4: 225.28 | D4: 106.03 | E4: 1.0229 | F4: 230.71 | G4: 203.96 | H4: 165.89 | I4: 175.58 | J4: 111.64 | K4: 199.99
A5: 42948 | B5: 163.18 | C5: 237.06 | D5: 107.27 | E5: 1.0436 | F5: 240.94 | G5: 210.6 | H5: 171.77 | I5: 181.73 | J5: 111.65 | K5: 205.23
A6: 42979 | B6: 166.4 | C6: 234.42 | D6: 107.95 | E6: 1.0473 | F6: 243.17 | G6: 210.06 | H6: 173.27 | I6: 183.86 | J6: 111.66 | K6: 206.59
A7: 43009 | B7: 163.64 | C7: 230.7 | D7: 106.97 | E7: 1.0537 | F7: 244.68 | G7: 213.91 | H7: 174.18 | I7: 186.1 | J7: 111.67 | K7: 206.79
A8: 43040 | B8: 170.83 | C8: 244.01 | D8: 106.54 | E8: 1.069 | F8: 252.96 | G8: 217.7 | H8: 179.47 | I8: 188.23 | J8: 111.68 | K8: 210.97
A9: 43070 | B9: 172.79 | C9: 239.77 | D9: 107.68 | E9: 1.079 | F9: 254.36 | G9: 224.34 | H9: 180.81 | I9: 191.4 | J9: 111.69 | K9: 212.3
A10: 43101 | B10: 176.9 | C10: 247.49 | D10: 108.73 | E10: 1.0903 | F10: 260.8 | G10: 227.14 | H10: 184.8 | I10: 194.89 | J10: 111.7 | K10: 215.26
A11: 43132 | B11: 195.12 | C11: 258.25 | D11: 109.59 | E11: 1.1224 | F11: 277.3 | G11: 239.13 | H11: 195.44 | I11: 208.73 | J11: 111.71 | K11: 223.17
A12: 43160 | B12: 184.48 | C12: 247.66 | D12: 108.61 | E12: 1.0882 | F12: 263.47 | G12: 227.58 | H12: 186.72 | I12: 198.49 | J12: 111.72 | K12: 216.4
A13: 43191 | B13: 178.8 | C13: 243.67 | D13: 109.39 | E13: 1.0862 | F13: 259.01 | G13: 224.24 | H13: 183.96 | I13: 196.55 | J13: 111.73 | K13: 214.85
... A109: 46113 | B109: 179.92 | C109: 485.15 | D109: 120.08 | E109: 1.7468 | F109: 391.67 | G109: 495.61 | H109: 230.63 | I109: 432.87 | J109: 125.75 | K109: 261.69

Sheet correlation_matrix
A1: fund | B1: 中港基金 | C1: 亞洲股票基金 | D1: 亞洲債券基金 | E1: 核心累積基金 | F1: 增長組合 | G1: 北美股票基金 | H1: 基金經理精選退休基金 | I1: 美洲基金 | J1: 強積金保守基金 | K1: 均衡組合
A2: 中港基金 | B2: 1 | C2: 0.59207166 | D2: 0.48043214 | E2: 0.47839937 | F2: 0.79122489 | G2: 0.4008162 | H2: 0.75278523 | I2: 0.41943334 | J2: 0.094616868 | K2: 0.75312571
A3: 亞洲股票基金 | B3: 0.59207166 | C3: 1 | D3: 0.64154883 | E3: 0.86749335 | F3: 0.91151072 | G3: 0.80053688 | H3: 0.89855479 | I3: 0.8238955 | J3: 0.027393785 | K3: 0.89764511
A4: 亞洲債券基金 | B4: 0.48043214 | C4: 0.64154883 | D4: 1 | E4: 0.71714627 | F4: 0.67451452 | G4: 0.53868345 | H4: 0.69372581 | I4: 0.57090019 | J4: 0.15788796 | K4: 0.78825791
A5: 核心累積基金 | B5: 0.47839937 | C5: 0.86749335 | D5: 0.71714627 | E5: 1 | F5: 0.88895071 | G5: 0.95554378 | H5: 0.88634901 | I5: 0.96025488 | J5: 0.071772394 | K5: 0.90837801
A6: 增長組合 | B6: 0.79122489 | C6: 0.91151072 | D6: 0.67451452 | E6: 0.88895071 | F6: 1 | G6: 0.82406241 | H6: 0.98003976 | I6: 0.83539657 | J6: 0.065056867 | K6: 0.97919676
A7: 北美股票基金 | B7: 0.4008162 | C7: 0.80053688 | D7: 0.53868345 | E7: 0.95554378 | F7: 0.82406241 | G7: 1 | H7: 0.80435291 | I7: 0.98180537 | J7: 0.020078215 | K7: 0.80252288
A8: 基金經理精選退休基金 | B8: 0.75278523 | C8: 0.89855479 | D8: 0.69372581 | E8: 0.88634901 | F8: 0.98003976 | G8: 0.80435291 | H8: 1 | I8: 0.82145679 | J8: 0.04473356 | K8: 0.9783402
A9: 美洲基金 | B9: 0.41943334 | C9: 0.8238955 | D9: 0.57090019 | E9: 0.96025488 | F9: 0.83539657 | G9: 0.98180537 | H9: 0.82145679 | I9: 1 | J9: 0.031695568 | K9: 0.82173211
A10: 強積金保守基金 | B10: 0.094616868 | C10: 0.027393785 | D10: 0.15788796 | E10: 0.071772394 | F10: 0.065056867 | G10: 0.020078215 | H10: 0.04473356 | I10: 0.031695568 | J10: 1 | K10: 0.084759728
A11: 均衡組合 | B11: 0.75312571 | C11: 0.89764511 | D11: 0.78825791 | E11: 0.90837801 | F11: 0.97919676 | G11: 0.80252288 | H11: 0.9783402 | I11: 0.82173211 | J11: 0.084759728 | K11: 1

Sheet regression1
A1: 摘要輸出
A3: 迴歸統計
A4: R 的倍數 | B4: 0.078964741
A5: R 平方 | B5: 0.0062354303
A6: 調整的 R 平方 | B6: -0.0032289942
A7: 標準誤 | B7: 0.0010383197
A8: 觀察值個數 | B8: 107
A10: ANOVA
B11: 自由度 | C11: SS | D11: MS | E11: F | F11: 顯著值
A12: 迴歸 | B12: 1 | C12: 7.1028788e-07 | D12: 7.1028788e-07 | E12: 0.65882826 | F12: 0.41881016
A13: 殘差 | B13: 105 | C13: 0.00011320132 | D13: 1.0781078e-06
A14: 總和 | B14: 106 | C14: 0.00011391161
B16: 係數 | C16: 標準誤 | D16: t 統計 | E16: P-值 | F16: 下限 95% | G16: 上限 95% | H16: 下限 95.0% | I16: 上限 95.0%
A17: 截距 | B17: 0.0011098495 | C17: 0.00010050689 | D17: 11.042521 | E17: 2.8128687e-19 | F17: 0.00091056287 | G17: 0.0013091361 | H17: 0.00091056287 | I17: 0.0013091361
A18: Beta | B18: 0.0013562374 | C18: 0.0016708968 | D18: 0.81168236 | E18: 0.41881016 | F18: -0.0019568422 | G18: 0.004669317 | H18: -0.0019568422 | I18: 0.004669317

Sheet mpf_monthly_return
A1: Date | B1: =表格1_[[#Headers],[中港基金]] -> 中港基金 | C1: =表格1_[[#Headers],[亞洲股票基金]] -> 亞洲股票基金 | D1: =表格1_[[#Headers],[亞洲債券基金]] -> 亞洲債券基金 | E1: =表格1_[[#Headers],[核心累積基金]] -> 核心累積基金 | F1: =表格1_[[#Headers],[增長組合]] -> 增長組合 | G1: =表格1_[[#Headers],[北美股票基金]] -> 北美股票基金 | H1: =表格1_[[#Headers],[基金經理精選退休基金]] -> 基金經理精選退休基金 | I1: =表格1_[[#Headers],[美洲基金]] -> 美洲基金 | J1: =表格1_[[#Headers],[強積金保守基金]] -> 強積金保守基金 | K1: =表格1_[[#Headers],[均衡組合]] -> 均衡組合
A2: 42856 | B2: =LN(mpf_monthly_price!B3/mpf_monthly_price!B2) -> 0.043967585 | C2: =LN(mpf_monthly_price!C3/mpf_monthly_price!C2) -> 0.014513245 | D2: =LN(mpf_monthly_price!D3/mpf_monthly_price!D2) -> 0.01256561 | E2: =LN(mpf_monthly_price!E3/mpf_monthly_price!E2) -> 0.013259537 | F2: =LN(mpf_monthly_price!F3/mpf_monthly_price!F2) -> 0.032031051 | G2: =LN(mpf_monthly_price!G3/mpf_monthly_price!G2) -> 0.017316236 | H2: =LN(mpf_monthly_price!H3/mpf_monthly_price!H2) -> 0.024583614 | I2: =LN(mpf_monthly_price!I3/mpf_monthly_price!I2) -> 0.011450288 | ... K2: =LN(mpf_monthly_price!K3/mpf_monthly_price!K2) -> 0.019185119
A3: 42887 | B3: =LN(mpf_monthly_price!B4/mpf_monthly_price!B3) -> 0.0054776576 | C3: =LN(mpf_monthly_price!C4/mpf_monthly_price!C3) -> 0.023671073 | D3: =LN(mpf_monthly_price!D4/mpf_monthly_price!D3) -> 0.0030225772 | E3: =LN(mpf_monthly_price!E4/mpf_monthly_price!E3) -> -0.0019533164 | F3: =LN(mpf_monthly_price!F4/mpf_monthly_price!F3) -> 0.0045180145 | G3: =LN(mpf_monthly_price!G4/mpf_monthly_price!G3) -> -0.0024484611 | H3: =LN(mpf_monthly_price!H4/mpf_monthly_price!H3) -> 0.0045918756 | I3: =LN(mpf_monthly_price!I4/mpf_monthly_price!I3) -> -0.00051245553 | ... K3: =LN(mpf_monthly_price!K4/mpf_monthly_price!K3) -> 0.0027037869
A4: 42917 | B4: =LN(mpf_monthly_price!B5/mpf_monthly_price!B4) -> 0.07136818 | C4: =LN(mpf_monthly_price!C5/mpf_monthly_price!C4) -> 0.050969201 | D4: =LN(mpf_monthly_price!D5/mpf_monthly_price!D4) -> 0.011626948 | E4: =LN(mpf_monthly_price!E5/mpf_monthly_price!E4) -> 0.020034544 | F4: =LN(mpf_monthly_price!F5/mpf_monthly_price!F4) -> 0.043386429 | G4: =LN(mpf_monthly_price!G5/mpf_monthly_price!G4) -> 0.032036704 | H4: =LN(mpf_monthly_price!H5/mpf_monthly_price!H4) -> 0.034831455 | I4: =LN(mpf_monthly_price!I5/mpf_monthly_price!I4) -> 0.03442729 | ... K4: =LN(mpf_monthly_price!K5/mpf_monthly_price!K4) -> 0.025863936
A5: 42948 | B5: =LN(mpf_monthly_price!B6/mpf_monthly_price!B5) -> 0.019540642 | C5: =LN(mpf_monthly_price!C6/mpf_monthly_price!C5) -> -0.011198895 | D5: =LN(mpf_monthly_price!D6/mpf_monthly_price!D5) -> 0.0063191364 | E5: =LN(mpf_monthly_price!E6/mpf_monthly_price!E5) -> 0.0035391495 | F5: =LN(mpf_monthly_price!F6/mpf_monthly_price!F5) -> 0.0092128474 | G5: =LN(mpf_monthly_price!G6/mpf_monthly_price!G5) -> -0.0025673955 | H5: =LN(mpf_monthly_price!H6/mpf_monthly_price!H5) -> 0.0086946989 | I5: =LN(mpf_monthly_price!I6/mpf_monthly_price!I5) -> 0.011652529 | ... K5: =LN(mpf_monthly_price!K6/mpf_monthly_price!K5) -> 0.0066048514
A6: 42979 | B6: =LN(mpf_monthly_price!B7/mpf_monthly_price!B6) -> -0.016725635 | C6: =LN(mpf_monthly_price!C7/mpf_monthly_price!C6) -> -0.015996213 | D6: =LN(mpf_monthly_price!D7/mpf_monthly_price!D6) -> -0.0091197356 | E6: =LN(mpf_monthly_price!E7/mpf_monthly_price!E6) -> 0.0060923558 | F6: =LN(mpf_monthly_price!F7/mpf_monthly_price!F6) -> 0.0061904472 | G6: =LN(mpf_monthly_price!G7/mpf_monthly_price!G6) -> 0.018162162 | H6: =LN(mpf_monthly_price!H7/mpf_monthly_price!H6) -> 0.0052381757 | I6: =LN(mpf_monthly_price!I7/mpf_monthly_price!I6) -> 0.012109565 | ... K6: =LN(mpf_monthly_price!K7/mpf_monthly_price!K6) -> 0.00096763276
A7: 43009 | B7: =LN(mpf_monthly_price!B8/mpf_monthly_price!B7) -> 0.043000017 | C7: =LN(mpf_monthly_price!C8/mpf_monthly_price!C7) -> 0.056091043 | D7: =LN(mpf_monthly_price!D8/mpf_monthly_price!D7) -> -0.0040279198 | E7: =LN(mpf_monthly_price!E8/mpf_monthly_price!E7) -> 0.014415852 | F7: =LN(mpf_monthly_price!F8/mpf_monthly_price!F7) -> 0.033280139 | G7: =LN(mpf_monthly_price!G8/mpf_monthly_price!G7) -> 0.017562602 | H7: =LN(mpf_monthly_price!H8/mpf_monthly_price!H7) -> 0.029918816 | I7: =LN(mpf_monthly_price!I8/mpf_monthly_price!I7) -> 0.011380456 | ... K7: =LN(mpf_monthly_price!K8/mpf_monthly_price!K7) -> 0.020012158
A8: 43040 | B8: =LN(mpf_monthly_price!B9/mpf_monthly_price!B8) -> 0.011408074 | C8: =LN(mpf_monthly_price!C9/mpf_monthly_price!C8) -> -0.017529078 | D8: =LN(mpf_monthly_price!D9/mpf_monthly_price!D8) -> 0.010643364 | E8: =LN(mpf_monthly_price!E9/mpf_monthly_price!E8) -> 0.0093110542 | F8: =LN(mpf_monthly_price!F9/mpf_monthly_price!F8) -> 0.0055192129 | G8: =LN(mpf_monthly_price!G9/mpf_monthly_price!G8) -> 0.03004479 | H8: =LN(mpf_monthly_price!H9/mpf_monthly_price!H8) -> 0.0074386931 | I8: =LN(mpf_monthly_price!I9/mpf_monthly_price!I8) -> 0.01670086 | ... K8: =LN(mpf_monthly_price!K9/mpf_monthly_price!K8) -> 0.0062844254
A9: 43070 | B9: =LN(mpf_monthly_price!B10/mpf_monthly_price!B9) -> 0.023507617 | C9: =LN(mpf_monthly_price!C10/mpf_monthly_price!C9) -> 0.031690047 | D9: =LN(mpf_monthly_price!D10/mpf_monthly_price!D9) -> 0.0097038791 | E9: =LN(mpf_monthly_price!E10/mpf_monthly_price!E9) -> 0.010418201 | F9: =LN(mpf_monthly_price!F10/mpf_monthly_price!F9) -> 0.025003244 | G9: =LN(mpf_monthly_price!G10/mpf_monthly_price!G9) -> 0.012403809 | H9: =LN(mpf_monthly_price!H10/mpf_monthly_price!H9) -> 0.021827403 | I9: =LN(mpf_monthly_price!I10/mpf_monthly_price!I9) -> 0.018069818 | ... K9: =LN(mpf_monthly_price!K10/mpf_monthly_price!K9) -> 0.013846231
A10: 43101 | B10: =LN(mpf_monthly_price!B11/mpf_monthly_price!B10) -> 0.098030153 | C10: =LN(mpf_monthly_price!C11/mpf_monthly_price!C10) -> 0.042557931 | D10: =LN(mpf_monthly_price!D11/mpf_monthly_price!D10) -> 0.0078783845 | E10: =LN(mpf_monthly_price!E11/mpf_monthly_price!E10) -> 0.029016362 | F10: =LN(mpf_monthly_price!F11/mpf_monthly_price!F10) -> 0.061346123 | G10: =LN(mpf_monthly_price!G11/mpf_monthly_price!G10) -> 0.05144077 | H10: =LN(mpf_monthly_price!H11/mpf_monthly_price!H10) -> 0.055979268 | I10: =LN(mpf_monthly_price!I11/mpf_monthly_price!I10) -> 0.068606254 | ... K10: =LN(mpf_monthly_price!K11/mpf_monthly_price!K10) -> 0.036087213
A11: 43132 | B11: =LN(mpf_monthly_price!B12/mpf_monthly_price!B11) -> -0.056073697 | C11: =LN(mpf_monthly_price!C12/mpf_monthly_price!C11) -> -0.04187127 | D11: =LN(mpf_monthly_price!D12/mpf_monthly_price!D11) -> -0.0089826452 | E11: =LN(mpf_monthly_price!E12/mpf_monthly_price!E11) -> -0.030944295 | F11: =LN(mpf_monthly_price!F12/mpf_monthly_price!F11) -> -0.051160443 | G11: =LN(mpf_monthly_price!G12/mpf_monthly_price!G11) -> -0.049505512 | H11: =LN(mpf_monthly_price!H12/mpf_monthly_price!H11) -> -0.045643258 | I11: =LN(mpf_monthly_price!I12/mpf_monthly_price!I11) -> -0.05030283 | ... K11: =LN(mpf_monthly_price!K12/mpf_monthly_price!K11) -> -0.030805266
A12: 43160 | B12: =LN(mpf_monthly_price!B13/mpf_monthly_price!B12) -> -0.031273194 | C12: =LN(mpf_monthly_price!C13/mpf_monthly_price!C12) -> -0.016241987 | D12: =LN(mpf_monthly_price!D13/mpf_monthly_price!D12) -> 0.0071559938 | E12: =LN(mpf_monthly_price!E13/mpf_monthly_price!E12) -> -0.0018395885 | F12: =LN(mpf_monthly_price!F13/mpf_monthly_price!F12) -> -0.017072839 | G12: =LN(mpf_monthly_price!G13/mpf_monthly_price!G12) -> -0.014784918 | H12: =LN(mpf_monthly_price!H13/mpf_monthly_price!H12) -> -0.014891826 | I12: =LN(mpf_monthly_price!I13/mpf_monthly_price!I12) -> -0.0098218692 | ... K12: =LN(mpf_monthly_price!K13/mpf_monthly_price!K12) -> -0.0071884368
A13: 43191 | B13: =LN(mpf_monthly_price!B14/mpf_monthly_price!B13) -> 0.02529264 | C13: =LN(mpf_monthly_price!C14/mpf_monthly_price!C13) -> 0.023243182 | D13: =LN(mpf_monthly_price!D14/mpf_monthly_price!D13) -> -0.014178105 | E13: =LN(mpf_monthly_price!E14/mpf_monthly_price!E13) -> 0.0034923296 | F13: =LN(mpf_monthly_price!F14/mpf_monthly_price!F13) -> 0.010446767 | G13: =LN(mpf_monthly_price!G14/mpf_monthly_price!G13) -> 0.0091446458 | H13: =LN(mpf_monthly_price!H14/mpf_monthly_price!H13) -> 0.0081208827 | I13: =LN(mpf_monthly_price!I14/mpf_monthly_price!I13) -> -0.003465678 | ... K13: =LN(mpf_monthly_price!K14/mpf_monthly_price!K13) -> 0.0003722835
... A108: 46082 | B108: =LN(mpf_monthly_price!B109/mpf_monthly_price!B108) -> -0.029085988 | C108: =LN(mpf_monthly_price!C109/mpf_monthly_price!C108) -> -0.079873039 | D108: =LN(mpf_monthly_price!D109/mpf_monthly_price!D108) -> -0.012907675 | E108: =LN(mpf_monthly_price!E109/mpf_monthly_price!E108) -> -0.035430799 | F108: =LN(mpf_monthly_price!F109/mpf_monthly_price!F108) -> -0.049923858 | G108: =LN(mpf_monthly_price!G109/mpf_monthly_price!G108) -> -0.046692424 | H108: =LN(mpf_monthly_price!H109/mpf_monthly_price!H108) -> -0.041572699 | I108: =LN(mpf_monthly_price!I109/mpf_monthly_price!I108) -> -0.044328211 | ... K108: =LN(mpf_monthly_price!K109/mpf_monthly_price!K108) -> -0.035179601

Sheet mpf_cum_return
A1: Date | B1: =表格1_[[#Headers],[中港基金]] -> 中港基金 | C1: =表格1_[[#Headers],[亞洲股票基金]] -> 亞洲股票基金 | D1: =表格1_[[#Headers],[亞洲債券基金]] -> 亞洲債券基金 | E1: =表格1_[[#Headers],[核心累積基金]] -> 核心累積基金 | F1: =表格1_[[#Headers],[增長組合]] -> 增長組合 | G1: =表格1_[[#Headers],[北美股票基金]] -> 北美股票基金 | H1: =表格1_[[#Headers],[基金經理精選退休基金]] -> 基金經理精選退休基金 | I1: =表格1_[[#Headers],[美洲基金]] -> 美洲基金 | J1: =表格1_[[#Headers],[強積金保守基金]] -> 強積金保守基金 | K1: =表格1_[[#Headers],[均衡組合]] -> 均衡組合
A2: 42826 | B2: 1 | C2: 1 | D2: 1 | E2: 1 | F2: 1 | G2: 1 | H2: 1 | I2: 1 | J2: 1 | K2: 1
A3: 42856 | B3: =B2*(1+mpf_monthly_return!B2) -> 1.0439676 | C3: =C2*(1+mpf_monthly_return!C2) -> 1.0145132 | D3: =D2*(1+mpf_monthly_return!D2) -> 1.0125656 | E3: =E2*(1+mpf_monthly_return!E2) -> 1.0132595 | F3: =F2*(1+mpf_monthly_return!F2) -> 1.0320311 | G3: =G2*(1+mpf_monthly_return!G2) -> 1.0173162 | H3: =H2*(1+mpf_monthly_return!H2) -> 1.0245836 | I3: =I2*(1+mpf_monthly_return!I2) -> 1.0114503 | ... K3: =K2*(1+mpf_monthly_return!K2) -> 1.0191851
A4: 42887 | B4: =B3*(1+mpf_monthly_return!B3) -> 1.0496861 | C4: =C3*(1+mpf_monthly_return!C3) -> 1.0385279 | D4: =D3*(1+mpf_monthly_return!D3) -> 1.0156262 | E4: =E3*(1+mpf_monthly_return!E3) -> 1.0112803 | F4: =F3*(1+mpf_monthly_return!F3) -> 1.0366938 | G4: =G3*(1+mpf_monthly_return!G3) -> 1.0148254 | H4: =H3*(1+mpf_monthly_return!H3) -> 1.0292884 | I4: =I3*(1+mpf_monthly_return!I3) -> 1.010932 | ... K4: =K3*(1+mpf_monthly_return!K3) -> 1.0219408
A5: 42917 | B5: =B4*(1+mpf_monthly_return!B4) -> 1.1246003 | C5: =C4*(1+mpf_monthly_return!C4) -> 1.0914608 | D5: =D4*(1+mpf_monthly_return!D4) -> 1.0274348 | E5: =E4*(1+mpf_monthly_return!E4) -> 1.0315409 | F5: =F4*(1+mpf_monthly_return!F4) -> 1.0816722 | G5: =G4*(1+mpf_monthly_return!G4) -> 1.047337 | H5: =H4*(1+mpf_monthly_return!H4) -> 1.06514 | I5: =I4*(1+mpf_monthly_return!I4) -> 1.0457356 | ... K5: =K4*(1+mpf_monthly_return!K4) -> 1.0483722
A6: 42948 | B6: =B5*(1+mpf_monthly_return!B5) -> 1.1465757 | C6: =C5*(1+mpf_monthly_return!C5) -> 1.0792376 | D6: =D5*(1+mpf_monthly_return!D5) -> 1.0339273 | E6: =E5*(1+mpf_monthly_return!E5) -> 1.0351916 | F6: =F5*(1+mpf_monthly_return!F5) -> 1.0916375 | G6: =G5*(1+mpf_monthly_return!G5) -> 1.0446481 | H6: =H5*(1+mpf_monthly_return!H5) -> 1.0744011 | I6: =I5*(1+mpf_monthly_return!I5) -> 1.0579211 | ... K6: =K5*(1+mpf_monthly_return!K5) -> 1.0552965
A7: 42979 | B7: =B6*(1+mpf_monthly_return!B6) -> 1.1273985 | C7: =C6*(1+mpf_monthly_return!C6) -> 1.0619739 | D7: =D6*(1+mpf_monthly_return!D6) -> 1.0244982 | E7: =E6*(1+mpf_monthly_return!E6) -> 1.0414984 | F7: =F6*(1+mpf_monthly_return!F6) -> 1.0983952 | G7: =G6*(1+mpf_monthly_return!G6) -> 1.0636212 | H7: =H6*(1+mpf_monthly_return!H6) -> 1.080029 | I7: =I6*(1+mpf_monthly_return!I6) -> 1.070732 | ... K7: =K6*(1+mpf_monthly_return!K6) -> 1.0563177
A8: 43009 | B8: =B7*(1+mpf_monthly_return!B7) -> 1.1758766 | C8: =C7*(1+mpf_monthly_return!C7) -> 1.1215412 | D8: =D7*(1+mpf_monthly_return!D7) -> 1.0203716 | E8: =E7*(1+mpf_monthly_return!E7) -> 1.0565125 | F8: =F7*(1+mpf_monthly_return!F7) -> 1.13495 | G8: =G7*(1+mpf_monthly_return!G7) -> 1.0823011 | H8: =H7*(1+mpf_monthly_return!H7) -> 1.1123421 | I8: =I7*(1+mpf_monthly_return!I7) -> 1.0829175 | ... K8: =K7*(1+mpf_monthly_return!K7) -> 1.0774569
A9: 43040 | B9: =B8*(1+mpf_monthly_return!B8) -> 1.1892911 | C9: =C8*(1+mpf_monthly_return!C8) -> 1.1018816 | D9: =D8*(1+mpf_monthly_return!D8) -> 1.0312317 | E9: =E8*(1+mpf_monthly_return!E8) -> 1.0663497 | F9: =F8*(1+mpf_monthly_return!F8) -> 1.141214 | G9: =G8*(1+mpf_monthly_return!G8) -> 1.1148186 | H9: =H8*(1+mpf_monthly_return!H8) -> 1.1206165 | I9: =I8*(1+mpf_monthly_return!I8) -> 1.1010031 | ... K9: =K8*(1+mpf_monthly_return!K8) -> 1.0842281
A10: 43070 | B10: =B9*(1+mpf_monthly_return!B9) -> 1.2172485 | C10: =C9*(1+mpf_monthly_return!C9) -> 1.1368002 | D10: =D9*(1+mpf_monthly_return!D9) -> 1.0412387 | E10: =E9*(1+mpf_monthly_return!E9) -> 1.0774592 | F10: =F9*(1+mpf_monthly_return!F9) -> 1.1697481 | G10: =G9*(1+mpf_monthly_return!G9) -> 1.1286466 | H10: =H9*(1+mpf_monthly_return!H9) -> 1.1450767 | I10: =I9*(1+mpf_monthly_return!I9) -> 1.120898 | ... K10: =K9*(1+mpf_monthly_return!K9) -> 1.0992405
A11: 43101 | B11: =B10*(1+mpf_monthly_return!B10) -> 1.3365756 | C11: =C10*(1+mpf_monthly_return!C10) -> 1.1851801 | D11: =D10*(1+mpf_monthly_return!D10) -> 1.049442 | E11: =E10*(1+mpf_monthly_return!E10) -> 1.1087231 | F11: =F10*(1+mpf_monthly_return!F10) -> 1.2415076 | G11: =G10*(1+mpf_monthly_return!G10) -> 1.1867051 | H11: =H10*(1+mpf_monthly_return!H10) -> 1.2091772 | I11: =I10*(1+mpf_monthly_return!I10) -> 1.1977987 | ... K11: =K10*(1+mpf_monthly_return!K10) -> 1.1389091
A12: 43132 | B12: =B11*(1+mpf_monthly_return!B11) -> 1.2616288 | C12: =C11*(1+mpf_monthly_return!C11) -> 1.1355551 | D12: =D11*(1+mpf_monthly_return!D11) -> 1.0400152 | E12: =E11*(1+mpf_monthly_return!E11) -> 1.0744145 | F12: =F11*(1+mpf_monthly_return!F11) -> 1.1779915 | G12: =G11*(1+mpf_monthly_return!G11) -> 1.1279566 | H12: =H11*(1+mpf_monthly_return!H11) -> 1.1539864 | I12: =I11*(1+mpf_monthly_return!I11) -> 1.137546 | ... K12: =K11*(1+mpf_monthly_return!K11) -> 1.1038247
A13: 43160 | B13: =B12*(1+mpf_monthly_return!B12) -> 1.2221737 | C13: =C12*(1+mpf_monthly_return!C12) -> 1.1171114 | D13: =D12*(1+mpf_monthly_return!D12) -> 1.0474576 | E13: =E12*(1+mpf_monthly_return!E12) -> 1.072438 | F13: =F12*(1+mpf_monthly_return!F12) -> 1.1578798 | G13: =G12*(1+mpf_monthly_return!G12) -> 1.1112799 | H13: =H12*(1+mpf_monthly_return!H12) -> 1.1368015 | I13: =I12*(1+mpf_monthly_return!I12) -> 1.1263732 | ... K13: =K12*(1+mpf_monthly_return!K12) -> 1.0958899
A14: 43191 | B14: =B13*(1+mpf_monthly_return!B13) -> 1.2530857 | C14: =C13*(1+mpf_monthly_return!C13) -> 1.1430767 | D14: =D13*(1+mpf_monthly_return!D13) -> 1.0326066 | E14: =E13*(1+mpf_monthly_return!E13) -> 1.0761833 | F14: =F13*(1+mpf_monthly_return!F13) -> 1.1699759 | G14: =G13*(1+mpf_monthly_return!G13) -> 1.1214422 | H14: =H13*(1+mpf_monthly_return!H13) -> 1.1460333 | I14: =I13*(1+mpf_monthly_return!I13) -> 1.1224695 | ... K14: =K13*(1+mpf_monthly_return!K13) -> 1.0962979
... A109: 46082 | B109: =B108*(1+mpf_monthly_return!B108) -> 1.0574952 | C109: =C108*(1+mpf_monthly_return!C108) -> 1.9461854 | D109: =D108*(1+mpf_monthly_return!D108) -> 1.1354452 | E109: =E108*(1+mpf_monthly_return!E108) -> 1.6489533 | F109: =F108*(1+mpf_monthly_return!F108) -> 1.6160013 | G109: =G108*(1+mpf_monthly_return!G108) -> 2.1649626 | H109: =H108*(1+mpf_monthly_return!H108) -> 1.3622234 | I109: =I108*(1+mpf_monthly_return!I108) -> 2.1570877 | ... K109: =K108*(1+mpf_monthly_return!K108) -> 1.286579

Sheet VOO
A1: Date | B1: 收盤 | C1: return | D1: cum_return | E1: drawdown | F1: Downside
A2: 42856 | B2: 189.17189 | D2: 1
A3: 42887 | B3: 192.85815 | C3: =LN(B3/B2) -> 0.019298893 | D3: =D2*(1+C3) -> 1.0192989 | E3: =(B3-MAX(B$2:B3))/MAX(B$2:B3) -> 0 | F3: =IF(C3 < 0, C3, 0) -> 0
A4: 42919 | B4: 192.99451 | C4: =LN(B4/B3) -> 0.00070675964 | D4: =D3*(1+C4) -> 1.0200193 | E4: =(B4-MAX(B$2:B4))/MAX(B$2:B4) -> 0 | F4: =IF(C4 < 0, C4, 0) -> 0
A5: 42948 | B5: 196.9836 | C5: =LN(B5/B4) -> 0.020458734 | D5: =D4*(1+C5) -> 1.0408876 | E5: =(B5-MAX(B$2:B5))/MAX(B$2:B5) -> 0 | F5: =IF(C5 < 0, C5, 0) -> 0
A6: 42979 | B6: 197.45192 | C6: =LN(B6/B5) -> 0.0023746491 | D6: =D5*(1+C6) -> 1.0433593 | E6: =(B6-MAX(B$2:B6))/MAX(B$2:B6) -> 0 | F6: =IF(C6 < 0, C6, 0) -> 0
A7: 43010 | B7: 201.98471 | C7: =LN(B7/B6) -> 0.022696895 | D7: =D6*(1+C7) -> 1.0670404 | E7: =(B7-MAX(B$2:B7))/MAX(B$2:B7) -> 0 | F7: =IF(C7 < 0, C7, 0) -> 0
A8: 43040 | B8: 206.17726 | C8: =LN(B8/B7) -> 0.020544286 | D8: =D7*(1+C8) -> 1.0889619 | E8: =(B8-MAX(B$2:B8))/MAX(B$2:B8) -> 0 | F8: =IF(C8 < 0, C8, 0) -> 0
A9: 43070 | B9: 211.7209 | C9: =LN(B9/B8) -> 0.026532614 | D9: =D8*(1+C9) -> 1.1178549 | E9: =(B9-MAX(B$2:B9))/MAX(B$2:B9) -> 0 | F9: =IF(C9 < 0, C9, 0) -> 0
A10: 43102 | B10: 216.41034 | C10: =LN(B10/B9) -> 0.02190742 | D10: =D9*(1+C10) -> 1.1423443 | E10: =(B10-MAX(B$2:B10))/MAX(B$2:B10) -> 0 | F10: =IF(C10 < 0, C10, 0) -> 0
A11: 43132 | B11: 226.60513 | C11: =LN(B11/B10) -> 0.046032676 | D11: =D10*(1+C11) -> 1.1949294 | E11: =(B11-MAX(B$2:B11))/MAX(B$2:B11) -> 0 | F11: =IF(C11 < 0, C11, 0) -> 0
A12: 43160 | B12: 215.49953 | C12: =LN(B12/B11) -> -0.050250286 | D12: =D11*(1+C12) -> 1.1348839 | E12: =(B12-MAX(B$2:B12))/MAX(B$2:B12) -> -0.049008625 | F12: =IF(C12 < 0, C12, 0) -> -0.050250286
A13: 43192 | B13: 208.06502 | C13: =LN(B13/B12) -> -0.035108099 | D13: =D12*(1+C13) -> 1.0950403 | E13: =(B13-MAX(B$2:B13))/MAX(B$2:B13) -> -0.081816838 | F13: =IF(C13 < 0, C13, 0) -> -0.035108099
A14: 43221 | B14: 214.18875 | C14: =LN(B14/B13) -> 0.029007025 | D14: =D13*(1+C14) -> 1.1268041 | E14: =(B14-MAX(B$2:B14))/MAX(B$2:B14) -> -0.05479303 | F14: =IF(C14 < 0, C14, 0) -> 0
... A109: 46113 | B109: 602.29999 | C109: =LN(B109/B108) -> -0.043842344 | D109: =D108*(1+C109) -> 2.7850194 | E109: =(B109-MAX(B$2:B109))/MAX(B$2:B109) -> -0.055463306 | F109: =IF(C109 < 0, C109, 0) -> -0.043842344

Sheet 2800
A1: 日期 | B1: 收盤 | C1: return | D1: cum_return | E1: drawdown | F1: Downside
A2: 42857 | B2: 18.306339 | D2: 1 | E2: 0 | F2: =IF(C2 < 0, C2, 0) -> 0
A3: 42887 | B3: 19.192137 | C3: =LN(B3/B2) -> 0.047253244 | D3: =D2*(1+C3) -> 1.0472532 | E3: =(B3-MAX(B$2:B3))/MAX(B$2:B3) -> 0 | F3: =IF(C3 < 0, C3, 0) -> 0
A4: 42919 | B4: 19.376675 | C4: =LN(B4/B3) -> 0.0095693535 | D4: =D3*(1+C4) -> 1.0572748 | E4: =(B4-MAX(B$2:B4))/MAX(B$2:B4) -> 0 | F4: =IF(C4 < 0, C4, 0) -> 0
A5: 42948 | B5: 20.816086 | C5: =LN(B5/B4) -> 0.071656039 | D5: =D4*(1+C5) -> 1.1330349 | E5: =(B5-MAX(B$2:B5))/MAX(B$2:B5) -> 0 | F5: =IF(C5 < 0, C5, 0) -> 0
A6: 42979 | B6: 21.222071 | C6: =LN(B6/B5) -> 0.019315666 | D6: =D5*(1+C6) -> 1.1549202 | E6: =(B6-MAX(B$2:B6))/MAX(B$2:B6) -> 0 | F6: =IF(C6 < 0, C6, 0) -> 0
A7: 43011 | B7: 21.44352 | C7: =LN(B7/B6) -> 0.010380772 | D7: =D6*(1+C7) -> 1.1669092 | E7: =(B7-MAX(B$2:B7))/MAX(B$2:B7) -> 0 | F7: =IF(C7 < 0, C7, 0) -> 0
A8: 43040 | B8: 21.802477 | C8: =LN(B8/B7) -> 0.016601099 | D8: =D7*(1+C8) -> 1.1862812 | E8: =(B8-MAX(B$2:B8))/MAX(B$2:B8) -> 0 | F8: =IF(C8 < 0, C8, 0) -> 0
A9: 43070 | B9: 22.219568 | C9: =LN(B9/B8) -> 0.018949772 | D9: =D8*(1+C9) -> 1.2087609 | E9: =(B9-MAX(B$2:B9))/MAX(B$2:B9) -> 0 | F9: =IF(C9 < 0, C9, 0) -> 0
A10: 43102 | B10: 23.243336 | C10: =LN(B10/B9) -> 0.045045102 | D10: =D9*(1+C10) -> 1.2632097 | E10: =(B10-MAX(B$2:B10))/MAX(B$2:B10) -> 0 | F10: =IF(C10 < 0, C10, 0) -> 0
A11: 43132 | B11: 24.911701 | C11: =LN(B11/B10) -> 0.069319165 | D11: =D10*(1+C11) -> 1.3507743 | E11: =(B11-MAX(B$2:B11))/MAX(B$2:B11) -> 0 | F11: =IF(C11 < 0, C11, 0) -> 0
A12: 43160 | B12: 23.736263 | C12: =LN(B12/B11) -> -0.048333646 | D12: =D11*(1+C12) -> 1.2854865 | E12: =(B12-MAX(B$2:B12))/MAX(B$2:B12) -> -0.047184169 | F12: =IF(C12 < 0, C12, 0) -> -0.048333646
A13: 43193 | B13: 23.167503 | C13: =LN(B13/B12) -> -0.024253395 | D13: =D12*(1+C13) -> 1.2543091 | E13: =(B13-MAX(B$2:B13))/MAX(B$2:B13) -> -0.070015204 | F13: =IF(C13 < 0, C13, 0) -> -0.024253395
A14: 43222 | B14: 23.518999 | C14: =LN(B14/B13) -> 0.015057987 | D14: =D13*(1+C14) -> 1.2731964 | E14: =(B14-MAX(B$2:B14))/MAX(B$2:B14) -> -0.05590554 | F14: =IF(C14 < 0, C14, 0) -> 0
... A109: 46113 | B109: 25.353218 | C109: =LN(B109/B108) -> -0.028562361 | D109: =D108*(1+C109) -> 1.1458632 | E109: =(B109-MAX(B$2:B109))/MAX(B$2:B109) -> -0.067543593 | F109: =IF(C109 < 0, C109, 0) -> -0.028562361

Sheet stat
A1: info | B1: 中港基金 | C1: 亞洲股票基金 | D1: 亞洲債券基金 | E1: 核心累積基金 | F1: 增長組合 | G1: 北美股票基金 | H1: 基金經理精選退休基金 | I1: 美洲基金 | J1: 強積金保守基金 | K1: 均衡組合 | L1: VOO | M1: 2800 | S1: risk free rate(hibor 3m) | T1: =2.26214/100/12 -> 0.0018851167
A2: correlation coefficient with VOO | B2: =CORREL(VOO!$C3:$C109,mpf_monthly_return!B2:B108) -> 0.43198584 | C2: =CORREL(VOO!$C3:$C109,mpf_monthly_return!C2:C108) -> 0.80687716 | D2: =CORREL(VOO!$C3:$C109,mpf_monthly_return!D2:D108) -> 0.54389699 | E2: =CORREL(VOO!$C3:$C109,mpf_monthly_return!E2:E108) -> 0.94286663 | F2: =CORREL(VOO!$C3:$C109,mpf_monthly_return!F2:F108) -> 0.83369178 | G2: =CORREL(VOO!$C3:$C109,mpf_monthly_return!G2:G108) -> 0.97078463 | H2: =CORREL(VOO!$C3:$C109,mpf_monthly_return!H2:H108) -> 0.82130906 | I2: =CORREL(VOO!$C3:$C109,mpf_monthly_return!I2:I108) -> 0.96537699 | ... K2: =CORREL(VOO!$C3:$C109,mpf_monthly_return!K2:K108) -> 0.81693078
A3: correlation coefficient with 2800 | B3: =CORREL('2800'!$C3:$C109,mpf_monthly_return!B2:B108) -> 0.94603115 | C3: =CORREL('2800'!$C3:$C109,mpf_monthly_return!C2:C108) -> 0.54727563 | D3: =CORREL('2800'!$C3:$C109,mpf_monthly_return!D2:D108) -> 0.4606612 | E3: =CORREL('2800'!$C3:$C109,mpf_monthly_return!E2:E108) -> 0.46516412 | F3: =CORREL('2800'!$C3:$C109,mpf_monthly_return!F2:F108) -> 0.75873639 | G3: =CORREL('2800'!$C3:$C109,mpf_monthly_return!G2:G108) -> 0.39023258 | H3: =CORREL('2800'!$C3:$C109,mpf_monthly_return!H2:H108) -> 0.7234672 | I3: =CORREL('2800'!$C3:$C109,mpf_monthly_return!I2:I108) -> 0.40926522 | ... K3: =CORREL('2800'!$C3:$C109,mpf_monthly_return!K2:K108) -> 0.72533949
A4: average return | B4: =AVERAGE(mpf_monthly_return!B2:B108) -> 0.0020417929 | C4: =AVERAGE(mpf_monthly_return!C2:C108) -> 0.007526153 | D4: =AVERAGE(mpf_monthly_return!D2:D108) -> 0.0013086383 | E4: =AVERAGE(mpf_monthly_return!E2:E108) -> 0.0051070097 | F4: =AVERAGE(mpf_monthly_return!F2:F108) -> 0.0052879178 | G4: =AVERAGE(mpf_monthly_return!G2:G108) -> 0.0084367589 | H4: =AVERAGE(mpf_monthly_return!H2:H108) -> 0.0033520118 | I4: =AVERAGE(mpf_monthly_return!I2:I108) -> 0.0085353318 | ... K4: =AVERAGE(mpf_monthly_return!K2:K108) -> 0.0027175901 | L4: =AVERAGE(VOO!C3:C109) -> 0.01082336 | M4: =AVERAGE('2800'!C3:C109) -> 0.0030435351
A5: standard deviation | B5: =_xlfn.STDEV.P(mpf_monthly_return!B2:B108) -> 0.055358234 | C5: =_xlfn.STDEV.P(mpf_monthly_return!C2:C108) -> 0.050055465 | D5: =_xlfn.STDEV.P(mpf_monthly_return!D2:D108) -> 0.01554801 | E5: =_xlfn.STDEV.P(mpf_monthly_return!E2:E108) -> 0.028953804 | F5: =_xlfn.STDEV.P(mpf_monthly_return!F2:F108) -> 0.039659602 | G5: =_xlfn.STDEV.P(mpf_monthly_return!G2:G108) -> 0.048491151 | H5: =_xlfn.STDEV.P(mpf_monthly_return!H2:H108) -> 0.030209562 | I5: =_xlfn.STDEV.P(mpf_monthly_return!I2:I108) -> 0.050773465 | ... K5: =_xlfn.STDEV.P(mpf_monthly_return!K2:K108) -> 0.026782985 | L5: =_xlfn.STDEV.P(VOO!C3:C109) -> 0.048289574 | M5: =_xlfn.STDEV.P('2800'!C3:C109) -> 0.06007442
A6: sharper ratio | B6: =(B4-$T1)/B5 -> 0.0028302252 | C6: =(C4-$T1)/C5 -> 0.11269571 | D6: =(D4-$T1)/D5 -> -0.037077306 | E6: =(E4-$T1)/E5 -> 0.11127702 | F6: =(F4-$T1)/F5 -> 0.085800183 | G6: =(G4-$T1)/G5 -> 0.13511006 | H6: =(H4-$T1)/H5 -> 0.048557313 | I6: =(I4-$T1)/I5 -> 0.13097816 | ... M6: =(M4-$T1)/M5 -> 0.019283057
A7: maxmium drawdown | B7: =MIN(max_dd!B2:B108) -> -0.47847478 | C7: =MIN(max_dd!C2:C108) -> -0.31097773 | D7: =MIN(max_dd!D2:D108) -> -0.18980239 | E7: =MIN(max_dd!E2:E108) -> -0.2040415 | F7: =MIN(max_dd!F2:F108) -> -0.29016641 | G7: =MIN(max_dd!G2:G108) -> -0.24294406 | H7: =MIN(max_dd!H2:H108) -> -0.24547203 | I7: =MIN(max_dd!I2:I108) -> -0.28711162 | ... K7: =MIN(max_dd!K2:K108) -> -0.2472265 | L7: =MIN(VOO!E3:E109) -> -0.23861767 | M7: =MIN('2800'!E2:E109) -> -0.44538717
A8: Calmar Ratio | B8: =B4/ABS(B7) -> 0.0042672947 | C8: =C4/ABS(C7) -> 0.024201581 | D8: =D4/ABS(D7) -> 0.0068947411 | E8: =E4/ABS(E7) -> 0.025029269 | F8: =F4/ABS(F7) -> 0.018223742 | G8: =G4/ABS(G7) -> 0.034727167 | H8: =H4/ABS(H7) -> 0.013655372 | I8: =I4/ABS(I7) -> 0.02972827 | J8: 0 | K8: =K4/ABS(K7) -> 0.010992309 | L8: =L4/ABS(L7) -> 0.045358588 | M8: =M4/ABS(M7) -> 0.0068334594
A9: Sortino Ratio | B9: =(B4-$T$1)/(SQRT(SUMSQ(downside!B3:B109) / COUNT(mpf_monthly_return!B2:B108))) -> 0.004229428 | C9: =(C4-$T$1)/(SQRT(SUMSQ(downside!C3:C109) / COUNT(mpf_monthly_return!C2:C108))) -> 0.16486175 | D9: =(D4-$T$1)/(SQRT(SUMSQ(downside!D3:D109) / COUNT(mpf_monthly_return!D2:D108))) -> -0.054528033 | E9: =(E4-$T$1)/(SQRT(SUMSQ(downside!E3:E109) / COUNT(mpf_monthly_return!E2:E108))) -> 0.16413056 | F9: =(F4-$T$1)/(SQRT(SUMSQ(downside!F3:F109) / COUNT(mpf_monthly_return!F2:F108))) -> 0.12815029 | G9: =(G4-$T$1)/(SQRT(SUMSQ(downside!G3:G109) / COUNT(mpf_monthly_return!G2:G108))) -> 0.199571 | H9: =(H4-$T$1)/(SQRT(SUMSQ(downside!H3:H109) / COUNT(mpf_monthly_return!H2:H108))) -> 0.070902824 | I9: =(I4-$T$1)/(SQRT(SUMSQ(downside!I3:I109) / COUNT(mpf_monthly_return!I2:I108))) -> 0.19021336 | J9: 0 | K9: =(K4-$T$1)/(SQRT(SUMSQ(downside!K3:K109) / COUNT(mpf_monthly_return!K2:K108))) -> 0.045921496 | L9: =(L4-$T$1)/(SQRT(SUMSQ(VOO!F3:F109) / COUNT(VOO!C3:C109))) -> 0.26871826 | M9: =(M4-$T$1)/(SQRT(SUMSQ('2800'!F3:F109) / COUNT('2800'!C3:C109))) -> 0.029870723
A10: downside deviation | B10: =(SQRT(SUMSQ(downside!B3:B109)/COUNT(mpf_monthly_return!B2:B108))) -> 0.037044316 | C10: =(SQRT(SUMSQ(downside!C3:C109)/COUNT(mpf_monthly_return!C2:C108))) -> 0.034216768 | D10: =(SQRT(SUMSQ(downside!D3:D109)/COUNT(mpf_monthly_return!D2:D108))) -> 0.010572146 | E10: =(SQRT(SUMSQ(downside!E3:E109)/COUNT(mpf_monthly_return!E2:E108))) -> 0.019630062 | F10: =(SQRT(SUMSQ(downside!F3:F109)/COUNT(mpf_monthly_return!F2:F108))) -> 0.026553207 | G10: =(SQRT(SUMSQ(downside!G3:G109)/COUNT(mpf_monthly_return!G2:G108))) -> 0.032828629 | H10: =(SQRT(SUMSQ(downside!H3:H109)/COUNT(mpf_monthly_return!H2:H108))) -> 0.020688812 | I10: =(SQRT(SUMSQ(downside!I3:I109)/COUNT(mpf_monthly_return!I2:I108))) -> 0.034961872 | ... K10: =(SQRT(SUMSQ(downside!K3:K109)/COUNT(mpf_monthly_return!K2:K108))) -> 0.018128186 | L10: =(SQRT(SUMSQ(VOO!F3:F109)/COUNT(VOO!C3:C109))) -> 0.03326251 | M10: =SQRT(SUMSQ('2800'!F3:F109)/COUNT('2800'!C3:C109)) -> 0.038781066
A11: Beta with VOO | B11: =SLOPE(mpf_monthly_return!B2:B108,VOO!$C3:$C109) -> 0.49522022 | C11: =SLOPE(mpf_monthly_return!C2:C108,VOO!$C3:$C109) -> 0.83638368 | D11: =SLOPE(mpf_monthly_return!D2:D108,VOO!$C3:$C109) -> 0.17512095 | E11: =SLOPE(mpf_monthly_return!E2:E108,VOO!$C3:$C109) -> 0.56533063 | F11: =SLOPE(mpf_monthly_return!F2:F108,VOO!$C3:$C109) -> 0.68470027 | G11: =SLOPE(mpf_monthly_return!G2:G108,VOO!$C3:$C109) -> 0.97483701 | H11: =SLOPE(mpf_monthly_return!H2:H108,VOO!$C3:$C109) -> 0.51380422 | I11: =SLOPE(mpf_monthly_return!I2:I108,VOO!$C3:$C109) -> 1.0150335 | ... K11: =SLOPE(mpf_monthly_return!K2:K108,VOO!$C3:$C109) -> 0.45309665
A12: Apha with VOO | B12: {=INTERCEPT(mpf_monthly_return!B2:B108-$T1,VOO!$C3:$C109-$T1)} -> -0.0042697227 | C12: {=INTERCEPT(mpf_monthly_return!C2:C108-$T1,VOO!$C3:$C109-$T1)} -> -0.0018347649 | D12: {=INTERCEPT(mpf_monthly_return!D2:D108-$T1,VOO!$C3:$C109-$T1)} -> -0.0021417521 | E12: {=INTERCEPT(mpf_monthly_return!E2:E108-$T1,VOO!$C3:$C109-$T1)} -> -0.00183117 | F12: {=INTERCEPT(mpf_monthly_return!F2:F108-$T1,VOO!$C3:$C109-$T1)} -> -0.0027172168 | G12: {=INTERCEPT(mpf_monthly_return!G2:G108-$T1,VOO!$C3:$C109-$T1)} -> -0.0021616886 | H12: {=INTERCEPT(mpf_monthly_return!H2:H108-$T1,VOO!$C3:$C109-$T1)} -> -0.0031256122 | I12: {=INTERCEPT(mpf_monthly_return!I2:I108-$T1,VOO!$C3:$C109-$T1)} -> -0.0024224016 | ... K12: {=INTERCEPT(mpf_monthly_return!K2:K108-$T1,VOO!$C3:$C109-$T1)} -> -0.0032174149
A13: R-square with VOO | B13: =RSQ(mpf_monthly_return!B2:B108, VOO!$C3:$C109) -> 0.18661176 | C13: =RSQ(mpf_monthly_return!C2:C108, VOO!$C3:$C109) -> 0.65105075 | D13: =RSQ(mpf_monthly_return!D2:D108, VOO!$C3:$C109) -> 0.29582394 | E13: =RSQ(mpf_monthly_return!E2:E108, VOO!$C3:$C109) -> 0.88899747 | F13: =RSQ(mpf_monthly_return!F2:F108, VOO!$C3:$C109) -> 0.69504199 | G13: =RSQ(mpf_monthly_return!G2:G108, VOO!$C3:$C109) -> 0.94242281 | H13: =RSQ(mpf_monthly_return!H2:H108, VOO!$C3:$C109) -> 0.67454858 | I13: =RSQ(mpf_monthly_return!I2:I108, VOO!$C3:$C109) -> 0.93195274 | ... K13: =RSQ(mpf_monthly_return!K2:K108, VOO!$C3:$C109) -> 0.6673759
A14: Beta with 2800 | B14: =SLOPE(mpf_monthly_return!B2:B108,'2800'!$C3:$C109) -> 0.87176229 | C14: =SLOPE(mpf_monthly_return!C2:C108,'2800'!$C3:$C109) -> 0.45600334 | D14: =SLOPE(mpf_monthly_return!D2:D108,'2800'!$C3:$C109) -> 0.11922487 | E14: =SLOPE(mpf_monthly_return!E2:E108,'2800'!$C3:$C109) -> 0.2241931 | F14: =SLOPE(mpf_monthly_return!F2:F108,'2800'!$C3:$C109) -> 0.50089844 | G14: =SLOPE(mpf_monthly_return!G2:G108,'2800'!$C3:$C109) -> 0.31498976 | H14: =SLOPE(mpf_monthly_return!H2:H108,'2800'!$C3:$C109) -> 0.36380921 | I14: =SLOPE(mpf_monthly_return!I2:I108,'2800'!$C3:$C109) -> 0.34590119 | ... K14: =SLOPE(mpf_monthly_return!K2:K108,'2800'!$C3:$C109) -> 0.32337817
A15: Apha with 2800 | B15: {=INTERCEPT(mpf_monthly_return!B2:B108-$T1,'2800'!$C3:$C109-$T1)} -> -0.00085318928 | C15: {=INTERCEPT(mpf_monthly_return!C2:C108-$T1,'2800'!$C3:$C109-$T1)} -> 0.0051127936 | D15: {=INTERCEPT(mpf_monthly_return!D2:D108-$T1,'2800'!$C3:$C109-$T1)} -> -0.00071459063 | E15: {=INTERCEPT(mpf_monthly_return!E2:E108-$T1,'2800'!$C3:$C109-$T1)} -> 0.0029621836 | F15: {=INTERCEPT(mpf_monthly_return!F2:F108-$T1,'2800'!$C3:$C109-$T1)} -> 0.0028225511 | G15: {=INTERCEPT(mpf_monthly_return!G2:G108-$T1,'2800'!$C3:$C109-$T1)} -> 0.0061867523 | H15: {=INTERCEPT(mpf_monthly_return!H2:H108-$T1,'2800'!$C3:$C109-$T1)} -> 0.0010454519 | I15: {=INTERCEPT(mpf_monthly_return!I2:I108-$T1,'2800'!$C3:$C109-$T1)} -> 0.0062495168 | ... K15: {=INTERCEPT(mpf_monthly_return!K2:K108-$T1,'2800'!$C3:$C109-$T1)} -> 0.00045786616
